Workbook

Sheet Resultado_Anual
A1: Utilidades anuales — ventana 4 h, arbitraje a costo marginal (spot), sin PPA
A2: Carga 4 h en banda solar; venta 4 h en banda nocturna. Período base 2023–2026 (2022 se muestra como contexto; excluido del caso base por ser previo a la saturación solar, carga 45 > PPA 28). Volúmenes 6,57 / 5,46 GWh y PPA enlazados desde Supuestos.
A4: Año | B4: P. carga medio (USD/MWh) | C4: P. venta medio (USD/MWh) | D4: Spread (USD/MWh) | E4: Ingreso venta (USD/año) | F4: Costo carga spot (USD/año) | G4: Margen bruto (USD/año) | H4: Costo si PPA $28 (USD/año) | I4: Sobrecosto del PPA (USD/año)
A5: 2022 | B5: =AVERAGEIF(Despacho_Diario!$B$4:$B$1589,$A5,Despacho_Diario!$C$4:$C$1589) -> 45.026281 | C5: =AVERAGEIF(Despacho_Diario!$B$4:$B$1589,$A5,Despacho_Diario!$D$4:$D$1589) -> 184.824 | D5: =C5-B5 -> 139.79772 | E5: =Supuestos!$B$17*C5 -> 1009139 | F5: =Supuestos!$B$16*B5 -> 295822.66 | G5: =E5-F5 -> 713316.37 | H5: =Supuestos!$B$16*Supuestos!$B$10 -> 183960 | I5: =H5-F5 -> -111862.66
A6: 2023 | B6: =AVERAGEIF(Despacho_Diario!$B$4:$B$1589,$A6,Despacho_Diario!$C$4:$C$1589) -> 19.892925 | C6: =AVERAGEIF(Despacho_Diario!$B$4:$B$1589,$A6,Despacho_Diario!$D$4:$D$1589) -> 143.14328 | D6: =C6-B6 -> 123.25036 | E6: =Supuestos!$B$17*C6 -> 781562.31 | F6: =Supuestos!$B$16*B6 -> 130696.52 | G6: =E6-F6 -> 650865.8 | H6: =Supuestos!$B$16*Supuestos!$B$10 -> 183960 | I6: =H6-F6 -> 53263.485
A7: 2024 | B7: =AVERAGEIF(Despacho_Diario!$B$4:$B$1589,$A7,Despacho_Diario!$C$4:$C$1589) -> 8.0611234 | C7: =AVERAGEIF(Despacho_Diario!$B$4:$B$1589,$A7,Despacho_Diario!$D$4:$D$1589) -> 93.790125 | D7: =C7-B7 -> 85.729002 | E7: =Supuestos!$B$17*C7 -> 512094.08 | F7: =Supuestos!$B$16*B7 -> 52961.581 | G7: =E7-F7 -> 459132.5 | H7: =Supuestos!$B$16*Supuestos!$B$10 -> 183960 | I7: =H7-F7 -> 130998.42
A8: 2025 | B8: =AVERAGEIF(Despacho_Diario!$B$4:$B$1589,$A8,Despacho_Diario!$C$4:$C$1589) -> 24.007278 | C8: =AVERAGEIF(Despacho_Diario!$B$4:$B$1589,$A8,Despacho_Diario!$D$4:$D$1589) -> 113.03888 | D8: =C8-B8 -> 89.031607 | E8: =Supuestos!$B$17*C8 -> 617192.31 | F8: =Supuestos!$B$16*B8 -> 157727.81 | G8: =E8-F8 -> 459464.49 | H8: =Supuestos!$B$16*Supuestos!$B$10 -> 183960 | I8: =H8-F8 -> 26232.185
A9: 2026 | B9: =AVERAGEIF(Despacho_Diario!$B$4:$B$1589,$A9,Despacho_Diario!$C$4:$C$1589) -> 9.5974672 | C9: =AVERAGEIF(Despacho_Diario!$B$4:$B$1589,$A9,Despacho_Diario!$D$4:$D$1589) -> 84.992198 | D9: =C9-B9 -> 75.394731 | E9: =Supuestos!$B$17*C9 -> 464057.4 | F9: =Supuestos!$B$16*B9 -> 63055.36 | G9: =E9-F9 -> 401002.04 | H9: =Supuestos!$B$16*Supuestos!$B$10 -> 183960 | I9: =H9-F9 -> 120904.64
A10: Base 23–26 | B10: =AVERAGE(B6:B9) -> 15.389698 | C10: =AVERAGE(C6:C9) -> 108.74112 | D10: =C10-B10 -> 93.351424 | E10: =Supuestos!$B$17*C10 -> 593726.53 | F10: =Supuestos!$B$16*B10 -> 101110.32 | G10: =E10-F10 -> 492616.21 | H10: =Supuestos!$B$16*Supuestos!$B$10 -> 183960 | I10: =H10-F10 -> 82849.682
A12: Ventana de 4 h, carga 100% en banda solar. El "sobrecosto del PPA" es el mayor costo anual de comprar la energía
A13: de carga a US$28/MWh en vez de cargar a spot. Positivo = el PPA destruye margen. Solo 2022 (previo a la saturación solar) lo favorecía.
A14: El caso base promedia 2023–2026, el período más largo en que el costo de carga es inferior al PPA en todos los años. 2022 (carga 45 > PPA 28) se excluye por ser previo a la saturación fotovoltaica del nodo.

Sheet Supuestos
A1: Panimávida BESS 13,2 kV — Utilidades por arbitraje a costo marginal · ventana 4 h · base 2023–2026
A2: RHO Generación · a solicitud del FIP CEHTA Capital · Base: 38.064 horas reales del Coordinador Eléctrico Nacional (Real Definitivo) · 2022-01-01 a 2026-05-22
A4: Supuesto | B4: Valor | C4: Unidad | D4: Fuente / nota
A5: Potencia del sistema (BESS) | B5: 9 | C5: MW | D5: Ficha de proyecto
A6: Capacidad de almacenamiento | B6: 36 | C6: MWh | D6: Ficha de proyecto (duración 4 h)
A7: Energía de carga anual | B7: 6.57 | C7: GWh/año | D7: Plan de operación (~182 ciclos completos de 4 h al año)
A8: Energía de descarga anual (venta) | B8: 5.46 | C8: GWh/año | D8: Carga × eficiencia round-trip
A9: Eficiencia round-trip implícita | B9: =B8/B7 -> 0.83105023 | C9: — | D9: Descarga ÷ Carga; conservadora vs 88% nominal
A10: Precio PPA de compra (referencia) | B10: 28 | C10: USD/MWh | D10: Oferta PPA en evaluación
A11: Banda solar (carga) | B11: 09–17 h | C11: hora-reloj | D11: Carga = horas más baratas DENTRO de esta banda
A12: Banda nocturna (venta) | B12: 19–07 h | C12: hora-reloj | D12: Venta = horas más caras DENTRO de esta banda
A13: Horas seleccionadas por ciclo | B13: 4 | C13: h | D13: 4 más baratas (carga) / 4 más caras (venta)
A15: Volúmenes anuales en MWh (derivados):
A16: Carga (MWh/año) | B16: =B7*1000 -> 6570
A17: Descarga / venta (MWh/año) | B17: =B8*1000 -> 5460
A19: METODOLOGÍA
A20: El proyecto selecciona, cada día operado, las 4 horas de menor costo marginal de la banda solar (09–17 h) para cargar y las
A21: 4 de mayor costo de la banda nocturna (19–07 h) para vender. Los volúmenes anuales (6,57 GWh de carga y 5,46 GWh de venta)
A22: corresponden al plan de operación previsto, equivalente a ~182 ciclos completos de 4 h al año (uno cada ~2 días). El precio
A23: anual es el promedio de los valores diarios (Despacho_Diario → Resultado_Anual). Fórmulas vivas sobre los datos crudos.
A25: Convención de color: azul = supuesto editable · negro = fórmula · verde = vínculo entre hojas.

Sheet Datos_CMg
A1: Fecha | B1: Hora | C1: CMg_USD_MWh | D1: Año
A2: 2022-01-01 | B2: 0 | C2: 81.24 | D2: 2022
A3: 2022-01-01 | B3: 1 | C3: 93.02 | D3: 2022
A4: 2022-01-01 | B4: 2 | C4: 186.53 | D4: 2022
A5: 2022-01-01 | B5: 3 | C5: 151.14 | D5: 2022
A6: 2022-01-01 | B6: 4 | C6: 120.03 | D6: 2022
A7: 2022-01-01 | B7: 5 | C7: 120.03 | D7: 2022
A8: 2022-01-01 | B8: 6 | C8: 107.32 | D8: 2022
A9: 2022-01-01 | B9: 7 | C9: 53.54 | D9: 2022
A10: 2022-01-01 | B10: 8 | C10: 0 | D10: 2022
A11: 2022-01-01 | B11: 9 | C11: 0 | D11: 2022
A12: 2022-01-01 | B12: 10 | C12: 0 | D12: 2022
A13: 2022-01-01 | B13: 11 | C13: 0 | D13: 2022
... A38065: 2026-05-22 | B38065: 23 | C38065: 61.901578 | D38065: 2026

Sheet Despacho_Diario
A1: Despacho diario — ciclo 4 h: carga en banda solar (09–17 h) y venta en banda nocturna (19–07 h)
A2: Carga = promedio de las 4 horas más baratas de la banda solar. Venta = promedio de las 4 más caras de la banda nocturna (anochecer 19–23 + madrugada 00–07). Fórmulas vivas sobre Datos_CMg.
A3: Fecha | B3: Año | C3: P_carga (USD/MWh) | D3: P_venta (USD/MWh) | E3: Spread (USD/MWh) | F3: aux t1 | G3: aux t2 | H3: aux t3 | I3: aux t4 | J3: aux m1 | K3: aux m2 | L3: aux m3 | M3: aux m4
A4: 2022-01-01 | B4: =Datos_CMg!$D$2 -> 2022 | C4: =(SMALL(Datos_CMg!$C$11:$C$19,1)+SMALL(Datos_CMg!$C$11:$C$19,2)+SMALL(Datos_CMg!$C$11:$C$19,3)+SMALL(Datos_CMg!$C$11:$C$19,4))/4 -> 0 | D4: =(LARGE($F4:$M4,1)+LARGE($F4:$M4,2)+LARGE($F4:$M4,3)+LARGE($F4:$M4,4))/4 -> 144.4325 | E4: =D4-C4 -> 144.4325 | F4: =LARGE(Datos_CMg!$C$21:$C$25,1) -> 95.35 | G4: =LARGE(Datos_CMg!$C$21:$C$25,2) -> 81.43 | H4: =LARGE(Datos_CMg!$C$21:$C$25,3) -> 75.14 | I4: =LARGE(Datos_CMg!$C$21:$C$25,4) -> 73.52 | J4: =LARGE(Datos_CMg!$C$2:$C$9,1) -> 186.53 | K4: =LARGE(Datos_CMg!$C$2:$C$9,2) -> 151.14 | L4: =LARGE(Datos_CMg!$C$2:$C$9,3) -> 120.03 | M4: =LARGE(Datos_CMg!$C$2:$C$9,4) -> 120.03
A5: 2022-01-02 | B5: =Datos_CMg!$D$26 -> 2022 | C5: =(SMALL(Datos_CMg!$C$35:$C$43,1)+SMALL(Datos_CMg!$C$35:$C$43,2)+SMALL(Datos_CMg!$C$35:$C$43,3)+SMALL(Datos_CMg!$C$35:$C$43,4))/4 -> 0 | D5: =(LARGE($F5:$M5,1)+LARGE($F5:$M5,2)+LARGE($F5:$M5,3)+LARGE($F5:$M5,4))/4 -> 88.8975 | E5: =D5-C5 -> 88.8975 | F5: =LARGE(Datos_CMg!$C$45:$C$49,1) -> 88.35 | G5: =LARGE(Datos_CMg!$C$45:$C$49,2) -> 88.04 | H5: =LARGE(Datos_CMg!$C$45:$C$49,3) -> 77.4 | I5: =LARGE(Datos_CMg!$C$45:$C$49,4) -> 75.58 | J5: =LARGE(Datos_CMg!$C$26:$C$33,1) -> 101.8 | K5: =LARGE(Datos_CMg!$C$26:$C$33,2) -> 75.25 | L5: =LARGE(Datos_CMg!$C$26:$C$33,3) -> 74.43 | M5: =LARGE(Datos_CMg!$C$26:$C$33,4) -> 68.94
A6: 2022-01-03 | B6: =Datos_CMg!$D$50 -> 2022 | C6: =(SMALL(Datos_CMg!$C$59:$C$67,1)+SMALL(Datos_CMg!$C$59:$C$67,2)+SMALL(Datos_CMg!$C$59:$C$67,3)+SMALL(Datos_CMg!$C$59:$C$67,4))/4 -> 0 | D6: =(LARGE($F6:$M6,1)+LARGE($F6:$M6,2)+LARGE($F6:$M6,3)+LARGE($F6:$M6,4))/4 -> 158.9325 | E6: =D6-C6 -> 158.9325 | F6: =LARGE(Datos_CMg!$C$69:$C$73,1) -> 180.97 | G6: =LARGE(Datos_CMg!$C$69:$C$73,2) -> 173.76 | H6: =LARGE(Datos_CMg!$C$69:$C$73,3) -> 160.79 | I6: =LARGE(Datos_CMg!$C$69:$C$73,4) -> 107.99 | J6: =LARGE(Datos_CMg!$C$50:$C$57,1) -> 120.21 | K6: =LARGE(Datos_CMg!$C$50:$C$57,2) -> 114.91 | L6: =LARGE(Datos_CMg!$C$50:$C$57,3) -> 90.59 | M6: =LARGE(Datos_CMg!$C$50:$C$57,4) -> 90.59
A7: 2022-01-04 | B7: =Datos_CMg!$D$74 -> 2022 | C7: =(SMALL(Datos_CMg!$C$83:$C$91,1)+SMALL(Datos_CMg!$C$83:$C$91,2)+SMALL(Datos_CMg!$C$83:$C$91,3)+SMALL(Datos_CMg!$C$83:$C$91,4))/4 -> 45.7675 | D7: =(LARGE($F7:$M7,1)+LARGE($F7:$M7,2)+LARGE($F7:$M7,3)+LARGE($F7:$M7,4))/4 -> 131.71 | E7: =D7-C7 -> 85.9425 | F7: =LARGE(Datos_CMg!$C$93:$C$97,1) -> 102.88 | G7: =LARGE(Datos_CMg!$C$93:$C$97,2) -> 94.04 | H7: =LARGE(Datos_CMg!$C$93:$C$97,3) -> 83.74 | I7: =LARGE(Datos_CMg!$C$93:$C$97,4) -> 79.84 | J7: =LARGE(Datos_CMg!$C$74:$C$81,1) -> 134.17 | K7: =LARGE(Datos_CMg!$C$74:$C$81,2) -> 134.17 | L7: =LARGE(Datos_CMg!$C$74:$C$81,3) -> 134.17 | M7: =LARGE(Datos_CMg!$C$74:$C$81,4) -> 124.33
A8: 2022-01-05 | B8: =Datos_CMg!$D$98 -> 2022 | C8: =(SMALL(Datos_CMg!$C$107:$C$115,1)+SMALL(Datos_CMg!$C$107:$C$115,2)+SMALL(Datos_CMg!$C$107:$C$115,3)+SMALL(Datos_CMg!$C$107:$C$115,4))/4 -> 41.345 | D8: =(LARGE($F8:$M8,1)+LARGE($F8:$M8,2)+LARGE($F8:$M8,3)+LARGE($F8:$M8,4))/4 -> 122.98 | E8: =D8-C8 -> 81.635 | F8: =LARGE(Datos_CMg!$C$117:$C$121,1) -> 149.3 | G8: =LARGE(Datos_CMg!$C$117:$C$121,2) -> 128.26 | H8: =LARGE(Datos_CMg!$C$117:$C$121,3) -> 113.81 | I8: =LARGE(Datos_CMg!$C$117:$C$121,4) -> 100.55 | J8: =LARGE(Datos_CMg!$C$98:$C$105,1) -> 88.03 | K8: =LARGE(Datos_CMg!$C$98:$C$105,2) -> 75.01 | L8: =LARGE(Datos_CMg!$C$98:$C$105,3) -> 75.01 | M8: =LARGE(Datos_CMg!$C$98:$C$105,4) -> 75.01
A9: 2022-01-06 | B9: =Datos_CMg!$D$122 -> 2022 | C9: =(SMALL(Datos_CMg!$C$131:$C$139,1)+SMALL(Datos_CMg!$C$131:$C$139,2)+SMALL(Datos_CMg!$C$131:$C$139,3)+SMALL(Datos_CMg!$C$131:$C$139,4))/4 -> 57.4525 | D9: =(LARGE($F9:$M9,1)+LARGE($F9:$M9,2)+LARGE($F9:$M9,3)+LARGE($F9:$M9,4))/4 -> 106.965 | E9: =D9-C9 -> 49.5125 | F9: =LARGE(Datos_CMg!$C$141:$C$145,1) -> 111.08 | G9: =LARGE(Datos_CMg!$C$141:$C$145,2) -> 111.08 | H9: =LARGE(Datos_CMg!$C$141:$C$145,3) -> 109.21 | I9: =LARGE(Datos_CMg!$C$141:$C$145,4) -> 96.49 | J9: =LARGE(Datos_CMg!$C$122:$C$129,1) -> 87.1 | K9: =LARGE(Datos_CMg!$C$122:$C$129,2) -> 83.51 | L9: =LARGE(Datos_CMg!$C$122:$C$129,3) -> 81.8 | M9: =LARGE(Datos_CMg!$C$122:$C$129,4) -> 81.41
A10: 2022-01-07 | B10: =Datos_CMg!$D$146 -> 2022 | C10: =(SMALL(Datos_CMg!$C$155:$C$163,1)+SMALL(Datos_CMg!$C$155:$C$163,2)+SMALL(Datos_CMg!$C$155:$C$163,3)+SMALL(Datos_CMg!$C$155:$C$163,4))/4 -> 53.0125 | D10: =(LARGE($F10:$M10,1)+LARGE($F10:$M10,2)+LARGE($F10:$M10,3)+LARGE($F10:$M10,4))/4 -> 207.075 | E10: =D10-C10 -> 154.0625 | F10: =LARGE(Datos_CMg!$C$165:$C$169,1) -> 216.76 | G10: =LARGE(Datos_CMg!$C$165:$C$169,2) -> 214.06 | H10: =LARGE(Datos_CMg!$C$165:$C$169,3) -> 183.5 | I10: =LARGE(Datos_CMg!$C$165:$C$169,4) -> 130.48 | J10: =LARGE(Datos_CMg!$C$146:$C$153,1) -> 198.74 | K10: =LARGE(Datos_CMg!$C$146:$C$153,2) -> 198.74 | L10: =LARGE(Datos_CMg!$C$146:$C$153,3) -> 194.27 | M10: =LARGE(Datos_CMg!$C$146:$C$153,4) -> 190.14
A11: 2022-01-08 | B11: =Datos_CMg!$D$170 -> 2022 | C11: =(SMALL(Datos_CMg!$C$179:$C$187,1)+SMALL(Datos_CMg!$C$179:$C$187,2)+SMALL(Datos_CMg!$C$179:$C$187,3)+SMALL(Datos_CMg!$C$179:$C$187,4))/4 -> 0 | D11: =(LARGE($F11:$M11,1)+LARGE($F11:$M11,2)+LARGE($F11:$M11,3)+LARGE($F11:$M11,4))/4 -> 222.2175 | E11: =D11-C11 -> 222.2175 | F11: =LARGE(Datos_CMg!$C$189:$C$193,1) -> 225.74 | G11: =LARGE(Datos_CMg!$C$189:$C$193,2) -> 225.32 | H11: =LARGE(Datos_CMg!$C$189:$C$193,3) -> 221.92 | I11: =LARGE(Datos_CMg!$C$189:$C$193,4) -> 193.1 | J11: =LARGE(Datos_CMg!$C$170:$C$177,1) -> 215.89 | K11: =LARGE(Datos_CMg!$C$170:$C$177,2) -> 212.27 | L11: =LARGE(Datos_CMg!$C$170:$C$177,3) -> 210.72 | M11: =LARGE(Datos_CMg!$C$170:$C$177,4) -> 209.65
A12: 2022-01-09 | B12: =Datos_CMg!$D$194 -> 2022 | C12: =(SMALL(Datos_CMg!$C$203:$C$211,1)+SMALL(Datos_CMg!$C$203:$C$211,2)+SMALL(Datos_CMg!$C$203:$C$211,3)+SMALL(Datos_CMg!$C$203:$C$211,4))/4 -> 0 | D12: =(LARGE($F12:$M12,1)+LARGE($F12:$M12,2)+LARGE($F12:$M12,3)+LARGE($F12:$M12,4))/4 -> 214.405 | E12: =D12-C12 -> 214.405 | F12: =LARGE(Datos_CMg!$C$213:$C$217,1) -> 217.61 | G12: =LARGE(Datos_CMg!$C$213:$C$217,2) -> 217.61 | H12: =LARGE(Datos_CMg!$C$213:$C$217,3) -> 203.17 | I12: =LARGE(Datos_CMg!$C$213:$C$217,4) -> 202.94 | J12: =LARGE(Datos_CMg!$C$194:$C$201,1) -> 211.2 | K12: =LARGE(Datos_CMg!$C$194:$C$201,2) -> 211.2 | L12: =LARGE(Datos_CMg!$C$194:$C$201,3) -> 206.6 | M12: =LARGE(Datos_CMg!$C$194:$C$201,4) -> 155.94
A13: 2022-01-10 | B13: =Datos_CMg!$D$218 -> 2022 | C13: =(SMALL(Datos_CMg!$C$227:$C$235,1)+SMALL(Datos_CMg!$C$227:$C$235,2)+SMALL(Datos_CMg!$C$227:$C$235,3)+SMALL(Datos_CMg!$C$227:$C$235,4))/4 -> 0 | D13: =(LARGE($F13:$M13,1)+LARGE($F13:$M13,2)+LARGE($F13:$M13,3)+LARGE($F13:$M13,4))/4 -> 179.6075 | E13: =D13-C13 -> 179.6075 | F13: =LARGE(Datos_CMg!$C$237:$C$241,1) -> 186.25 | G13: =LARGE(Datos_CMg!$C$237:$C$241,2) -> 186.25 | H13: =LARGE(Datos_CMg!$C$237:$C$241,3) -> 183.29 | I13: =LARGE(Datos_CMg!$C$237:$C$241,4) -> 155.79 | J13: =LARGE(Datos_CMg!$C$218:$C$225,1) -> 162.64 | K13: =LARGE(Datos_CMg!$C$218:$C$225,2) -> 159.61 | L13: =LARGE(Datos_CMg!$C$218:$C$225,3) -> 159.61 | M13: =LARGE(Datos_CMg!$C$218:$C$225,4) -> 159.61
A14: 2022-01-11 | B14: =Datos_CMg!$D$242 -> 2022 | C14: =(SMALL(Datos_CMg!$C$251:$C$259,1)+SMALL(Datos_CMg!$C$251:$C$259,2)+SMALL(Datos_CMg!$C$251:$C$259,3)+SMALL(Datos_CMg!$C$251:$C$259,4))/4 -> 0 | D14: =(LARGE($F14:$M14,1)+LARGE($F14:$M14,2)+LARGE($F14:$M14,3)+LARGE($F14:$M14,4))/4 -> 193.515 | E14: =D14-C14 -> 193.515 | F14: =LARGE(Datos_CMg!$C$261:$C$265,1) -> 207.49 | G14: =LARGE(Datos_CMg!$C$261:$C$265,2) -> 207.49 | H14: =LARGE(Datos_CMg!$C$261:$C$265,3) -> 173.67 | I14: =LARGE(Datos_CMg!$C$261:$C$265,4) -> 156.65 | J14: =LARGE(Datos_CMg!$C$242:$C$249,1) -> 179.54 | K14: =LARGE(Datos_CMg!$C$242:$C$249,2) -> 179.54 | L14: =LARGE(Datos_CMg!$C$242:$C$249,3) -> 114.23 | M14: =LARGE(Datos_CMg!$C$242:$C$249,4) -> 101.77
A15: 2022-01-12 | B15: =Datos_CMg!$D$266 -> 2022 | C15: =(SMALL(Datos_CMg!$C$275:$C$283,1)+SMALL(Datos_CMg!$C$275:$C$283,2)+SMALL(Datos_CMg!$C$275:$C$283,3)+SMALL(Datos_CMg!$C$275:$C$283,4))/4 -> 0 | D15: =(LARGE($F15:$M15,1)+LARGE($F15:$M15,2)+LARGE($F15:$M15,3)+LARGE($F15:$M15,4))/4 -> 134.945 | E15: =D15-C15 -> 134.945 | F15: =LARGE(Datos_CMg!$C$285:$C$289,1) -> 135.4 | G15: =LARGE(Datos_CMg!$C$285:$C$289,2) -> 135.4 | H15: =LARGE(Datos_CMg!$C$285:$C$289,3) -> 132.05 | I15: =LARGE(Datos_CMg!$C$285:$C$289,4) -> 113.09 | J15: =LARGE(Datos_CMg!$C$266:$C$273,1) -> 136.93 | K15: =LARGE(Datos_CMg!$C$266:$C$273,2) -> 127.72 | L15: =LARGE(Datos_CMg!$C$266:$C$273,3) -> 117.79 | M15: =LARGE(Datos_CMg!$C$266:$C$273,4) -> 98.99
A16: 2022-01-13 | B16: =Datos_CMg!$D$290 -> 2022 | C16: =(SMALL(Datos_CMg!$C$299:$C$307,1)+SMALL(Datos_CMg!$C$299:$C$307,2)+SMALL(Datos_CMg!$C$299:$C$307,3)+SMALL(Datos_CMg!$C$299:$C$307,4))/4 -> 0 | D16: =(LARGE($F16:$M16,1)+LARGE($F16:$M16,2)+LARGE($F16:$M16,3)+LARGE($F16:$M16,4))/4 -> 99.2875 | E16: =D16-C16 -> 99.2875 | F16: =LARGE(Datos_CMg!$C$309:$C$313,1) -> 100.12 | G16: =LARGE(Datos_CMg!$C$309:$C$313,2) -> 88.55 | H16: =LARGE(Datos_CMg!$C$309:$C$313,3) -> 81.47 | I16: =LARGE(Datos_CMg!$C$309:$C$313,4) -> 80.35 | J16: =LARGE(Datos_CMg!$C$290:$C$297,1) -> 101.2 | K16: =LARGE(Datos_CMg!$C$290:$C$297,2) -> 98.96 | L16: =LARGE(Datos_CMg!$C$290:$C$297,3) -> 96.87 | M16: =LARGE(Datos_CMg!$C$290:$C$297,4) -> 86.36
A17: 2022-01-14 | B17: =Datos_CMg!$D$314 -> 2022 | C17: =(SMALL(Datos_CMg!$C$323:$C$331,1)+SMALL(Datos_CMg!$C$323:$C$331,2)+SMALL(Datos_CMg!$C$323:$C$331,3)+SMALL(Datos_CMg!$C$323:$C$331,4))/4 -> 0 | D17: =(LARGE($F17:$M17,1)+LARGE($F17:$M17,2)+LARGE($F17:$M17,3)+LARGE($F17:$M17,4))/4 -> 87.62 | E17: =D17-C17 -> 87.62 | F17: =LARGE(Datos_CMg!$C$333:$C$337,1) -> 88.66 | G17: =LARGE(Datos_CMg!$C$333:$C$337,2) -> 87.67 | H17: =LARGE(Datos_CMg!$C$333:$C$337,3) -> 87.28 | I17: =LARGE(Datos_CMg!$C$333:$C$337,4) -> 86.87 | J17: =LARGE(Datos_CMg!$C$314:$C$321,1) -> 81.22 | K17: =LARGE(Datos_CMg!$C$314:$C$321,2) -> 81.22 | L17: =LARGE(Datos_CMg!$C$314:$C$321,3) -> 77.42 | M17: =LARGE(Datos_CMg!$C$314:$C$321,4) -> 75.44
A18: 2022-01-15 | B18: =Datos_CMg!$D$338 -> 2022 | C18: =(SMALL(Datos_CMg!$C$347:$C$355,1)+SMALL(Datos_CMg!$C$347:$C$355,2)+SMALL(Datos_CMg!$C$347:$C$355,3)+SMALL(Datos_CMg!$C$347:$C$355,4))/4 -> 0 | D18: =(LARGE($F18:$M18,1)+LARGE($F18:$M18,2)+LARGE($F18:$M18,3)+LARGE($F18:$M18,4))/4 -> 80.6725 | E18: =D18-C18 -> 80.6725 | F18: =LARGE(Datos_CMg!$C$357:$C$361,1) -> 80.74 | G18: =LARGE(Datos_CMg!$C$357:$C$361,2) -> 78.5 | H18: =LARGE(Datos_CMg!$C$357:$C$361,3) -> 74.07 | I18: =LARGE(Datos_CMg!$C$357:$C$361,4) -> 71.15 | J18: =LARGE(Datos_CMg!$C$338:$C$345,1) -> 80.65 | K18: =LARGE(Datos_CMg!$C$338:$C$345,2) -> 80.65 | L18: =LARGE(Datos_CMg!$C$338:$C$345,3) -> 80.65 | M18: =LARGE(Datos_CMg!$C$338:$C$345,4) -> 79.23
A19: 2022-01-16 | B19: =Datos_CMg!$D$362 -> 2022 | C19: =(SMALL(Datos_CMg!$C$371:$C$379,1)+SMALL(Datos_CMg!$C$371:$C$379,2)+SMALL(Datos_CMg!$C$371:$C$379,3)+SMALL(Datos_CMg!$C$371:$C$379,4))/4 -> 0 | D19: =(LARGE($F19:$M19,1)+LARGE($F19:$M19,2)+LARGE($F19:$M19,3)+LARGE($F19:$M19,4))/4 -> 81.975 | E19: =D19-C19 -> 81.975 | F19: =LARGE(Datos_CMg!$C$381:$C$385,1) -> 83.62 | G19: =LARGE(Datos_CMg!$C$381:$C$385,2) -> 81.96 | H19: =LARGE(Datos_CMg!$C$381:$C$385,3) -> 77.6 | I19: =LARGE(Datos_CMg!$C$381:$C$385,4) -> 73.25 | J19: =LARGE(Datos_CMg!$C$362:$C$369,1) -> 81.16 | K19: =LARGE(Datos_CMg!$C$362:$C$369,2) -> 81.16 | L19: =LARGE(Datos_CMg!$C$362:$C$369,3) -> 81.16 | M19: =LARGE(Datos_CMg!$C$362:$C$369,4) -> 81.11
A20: 2022-01-17 | B20: =Datos_CMg!$D$386 -> 2022 | C20: =(SMALL(Datos_CMg!$C$395:$C$403,1)+SMALL(Datos_CMg!$C$395:$C$403,2)+SMALL(Datos_CMg!$C$395:$C$403,3)+SMALL(Datos_CMg!$C$395:$C$403,4))/4 -> 0.5375 | D20: =(LARGE($F20:$M20,1)+LARGE($F20:$M20,2)+LARGE($F20:$M20,3)+LARGE($F20:$M20,4))/4 -> 84.2075 | E20: =D20-C20 -> 83.67 | F20: =LARGE(Datos_CMg!$C$405:$C$409,1) -> 88.32 | G20: =LARGE(Datos_CMg!$C$405:$C$409,2) -> 85.83 | H20: =LARGE(Datos_CMg!$C$405:$C$409,3) -> 81.42 | I20: =LARGE(Datos_CMg!$C$405:$C$409,4) -> 81.26 | J20: =LARGE(Datos_CMg!$C$386:$C$393,1) -> 80.38 | K20: =LARGE(Datos_CMg!$C$386:$C$393,2) -> 80.38 | L20: =LARGE(Datos_CMg!$C$386:$C$393,3) -> 80.38 | M20: =LARGE(Datos_CMg!$C$386:$C$393,4) -> 78.98
A21: 2022-01-18 | B21: =Datos_CMg!$D$410 -> 2022 | C21: =(SMALL(Datos_CMg!$C$419:$C$427,1)+SMALL(Datos_CMg!$C$419:$C$427,2)+SMALL(Datos_CMg!$C$419:$C$427,3)+SMALL(Datos_CMg!$C$419:$C$427,4))/4 -> 0 | D21: =(LARGE($F21:$M21,1)+LARGE($F21:$M21,2)+LARGE($F21:$M21,3)+LARGE($F21:$M21,4))/4 -> 84.13 | E21: =D21-C21 -> 84.13 | F21: =LARGE(Datos_CMg!$C$429:$C$433,1) -> 89.64 | G21: =LARGE(Datos_CMg!$C$429:$C$433,2) -> 88.26 | H21: =LARGE(Datos_CMg!$C$429:$C$433,3) -> 76.84 | I21: =LARGE(Datos_CMg!$C$429:$C$433,4) -> 72.71 | J21: =LARGE(Datos_CMg!$C$410:$C$417,1) -> 80.41 | K21: =LARGE(Datos_CMg!$C$410:$C$417,2) -> 78.21 | L21: =LARGE(Datos_CMg!$C$410:$C$417,3) -> 78.21 | M21: =LARGE(Datos_CMg!$C$410:$C$417,4) -> 77.31
A22: 2022-01-19 | B22: =Datos_CMg!$D$434 -> 2022 | C22: =(SMALL(Datos_CMg!$C$443:$C$451,1)+SMALL(Datos_CMg!$C$443:$C$451,2)+SMALL(Datos_CMg!$C$443:$C$451,3)+SMALL(Datos_CMg!$C$443:$C$451,4))/4 -> 0 | D22: =(LARGE($F22:$M22,1)+LARGE($F22:$M22,2)+LARGE($F22:$M22,3)+LARGE($F22:$M22,4))/4 -> 80.8 | E22: =D22-C22 -> 80.8 | F22: =LARGE(Datos_CMg!$C$453:$C$457,1) -> 82.74 | G22: =LARGE(Datos_CMg!$C$453:$C$457,2) -> 75.43 | H22: =LARGE(Datos_CMg!$C$453:$C$457,3) -> 72.56 | I22: =LARGE(Datos_CMg!$C$453:$C$457,4) -> 35.85 | J22: =LARGE(Datos_CMg!$C$434:$C$441,1) -> 80.59 | K22: =LARGE(Datos_CMg!$C$434:$C$441,2) -> 80.59 | L22: =LARGE(Datos_CMg!$C$434:$C$441,3) -> 79.28 | M22: =LARGE(Datos_CMg!$C$434:$C$441,4) -> 77.64
A23: 2022-01-20 | B23: =Datos_CMg!$D$458 -> 2022 | C23: =(SMALL(Datos_CMg!$C$467:$C$475,1)+SMALL(Datos_CMg!$C$467:$C$475,2)+SMALL(Datos_CMg!$C$467:$C$475,3)+SMALL(Datos_CMg!$C$467:$C$475,4))/4 -> 0 | D23: =(LARGE($F23:$M23,1)+LARGE($F23:$M23,2)+LARGE($F23:$M23,3)+LARGE($F23:$M23,4))/4 -> 82.77 | E23: =D23-C23 -> 82.77 | F23: =LARGE(Datos_CMg!$C$477:$C$481,1) -> 88.5 | G23: =LARGE(Datos_CMg!$C$477:$C$481,2) -> 87.88 | H23: =LARGE(Datos_CMg!$C$477:$C$481,3) -> 79.52 | I23: =LARGE(Datos_CMg!$C$477:$C$481,4) -> 75.18 | J23: =LARGE(Datos_CMg!$C$458:$C$465,1) -> 73.61 | K23: =LARGE(Datos_CMg!$C$458:$C$465,2) -> 73.43 | L23: =LARGE(Datos_CMg!$C$458:$C$465,3) -> 72.56 | M23: =LARGE(Datos_CMg!$C$458:$C$465,4) -> 70.94
A24: 2022-01-21 | B24: =Datos_CMg!$D$482 -> 2022 | C24: =(SMALL(Datos_CMg!$C$491:$C$499,1)+SMALL(Datos_CMg!$C$491:$C$499,2)+SMALL(Datos_CMg!$C$491:$C$499,3)+SMALL(Datos_CMg!$C$491:$C$499,4))/4 -> 0 | D24: =(LARGE($F24:$M24,1)+LARGE($F24:$M24,2)+LARGE($F24:$M24,3)+LARGE($F24:$M24,4))/4 -> 88.4175 | E24: =D24-C24 -> 88.4175 | F24: =LARGE(Datos_CMg!$C$501:$C$505,1) -> 90.64 | G24: =LARGE(Datos_CMg!$C$501:$C$505,2) -> 89.93 | H24: =LARGE(Datos_CMg!$C$501:$C$505,3) -> 86.55 | I24: =LARGE(Datos_CMg!$C$501:$C$505,4) -> 86.55 | J24: =LARGE(Datos_CMg!$C$482:$C$489,1) -> 74.65 | K24: =LARGE(Datos_CMg!$C$482:$C$489,2) -> 74.6 | L24: =LARGE(Datos_CMg!$C$482:$C$489,3) -> 73.77 | M24: =LARGE(Datos_CMg!$C$482:$C$489,4) -> 73.74
A25: 2022-01-22 | B25: =Datos_CMg!$D$506 -> 2022 | C25: =(SMALL(Datos_CMg!$C$515:$C$523,1)+SMALL(Datos_CMg!$C$515:$C$523,2)+SMALL(Datos_CMg!$C$515:$C$523,3)+SMALL(Datos_CMg!$C$515:$C$523,4))/4 -> 0 | D25: =(LARGE($F25:$M25,1)+LARGE($F25:$M25,2)+LARGE($F25:$M25,3)+LARGE($F25:$M25,4))/4 -> 82.715 | E25: =D25-C25 -> 82.715 | F25: =LARGE(Datos_CMg!$C$525:$C$529,1) -> 83.6 | G25: =LARGE(Datos_CMg!$C$525:$C$529,2) -> 80.19 | H25: =LARGE(Datos_CMg!$C$525:$C$529,3) -> 73.7 | I25: =LARGE(Datos_CMg!$C$525:$C$529,4) -> 73.7 | J25: =LARGE(Datos_CMg!$C$506:$C$513,1) -> 82.42 | K25: =LARGE(Datos_CMg!$C$506:$C$513,2) -> 82.42 | L25: =LARGE(Datos_CMg!$C$506:$C$513,3) -> 82.42 | M25: =LARGE(Datos_CMg!$C$506:$C$513,4) -> 78.5
A26: 2022-01-23 | B26: =Datos_CMg!$D$530 -> 2022 | C26: =(SMALL(Datos_CMg!$C$539:$C$547,1)+SMALL(Datos_CMg!$C$539:$C$547,2)+SMALL(Datos_CMg!$C$539:$C$547,3)+SMALL(Datos_CMg!$C$539:$C$547,4))/4 -> 0 | D26: =(LARGE($F26:$M26,1)+LARGE($F26:$M26,2)+LARGE($F26:$M26,3)+LARGE($F26:$M26,4))/4 -> 86.755 | E26: =D26-C26 -> 86.755 | F26: =LARGE(Datos_CMg!$C$549:$C$553,1) -> 94.06 | G26: =LARGE(Datos_CMg!$C$549:$C$553,2) -> 84.32 | H26: =LARGE(Datos_CMg!$C$549:$C$553,3) -> 84.32 | I26: =LARGE(Datos_CMg!$C$549:$C$553,4) -> 84.32 | J26: =LARGE(Datos_CMg!$C$530:$C$537,1) -> 75.08 | K26: =LARGE(Datos_CMg!$C$530:$C$537,2) -> 72.21 | L26: =LARGE(Datos_CMg!$C$530:$C$537,3) -> 72.04 | M26: =LARGE(Datos_CMg!$C$530:$C$537,4) -> 71.9
A27: 2022-01-24 | B27: =Datos_CMg!$D$554 -> 2022 | C27: =(SMALL(Datos_CMg!$C$563:$C$571,1)+SMALL(Datos_CMg!$C$563:$C$571,2)+SMALL(Datos_CMg!$C$563:$C$571,3)+SMALL(Datos_CMg!$C$563:$C$571,4))/4 -> 0 | D27: =(LARGE($F27:$M27,1)+LARGE($F27:$M27,2)+LARGE($F27:$M27,3)+LARGE($F27:$M27,4))/4 -> 149.7675 | E27: =D27-C27 -> 149.7675 | F27: =LARGE(Datos_CMg!$C$573:$C$577,1) -> 176.34 | G27: =LARGE(Datos_CMg!$C$573:$C$577,2) -> 176.34 | H27: =LARGE(Datos_CMg!$C$573:$C$577,3) -> 148.68 | I27: =LARGE(Datos_CMg!$C$573:$C$577,4) -> 97.71 | J27: =LARGE(Datos_CMg!$C$554:$C$561,1) -> 84.97 | K27: =LARGE(Datos_CMg!$C$554:$C$561,2) -> 84.92 | L27: =LARGE(Datos_CMg!$C$554:$C$561,3) -> 84.47 | M27: =LARGE(Datos_CMg!$C$554:$C$561,4) -> 83.98
A28: 2022-01-25 | B28: =Datos_CMg!$D$578 -> 2022 | C28: =(SMALL(Datos_CMg!$C$587:$C$595,1)+SMALL(Datos_CMg!$C$587:$C$595,2)+SMALL(Datos_CMg!$C$587:$C$595,3)+SMALL(Datos_CMg!$C$587:$C$595,4))/4 -> 26.2125 | D28: =(LARGE($F28:$M28,1)+LARGE($F28:$M28,2)+LARGE($F28:$M28,3)+LARGE($F28:$M28,4))/4 -> 156.0875 | E28: =D28-C28 -> 129.875 | F28: =LARGE(Datos_CMg!$C$597:$C$601,1) -> 168.71 | G28: =LARGE(Datos_CMg!$C$597:$C$601,2) -> 161.5 | H28: =LARGE(Datos_CMg!$C$597:$C$601,3) -> 156.92 | I28: =LARGE(Datos_CMg!$C$597:$C$601,4) -> 137.22 | J28: =LARGE(Datos_CMg!$C$578:$C$585,1) -> 99.58 | K28: =LARGE(Datos_CMg!$C$578:$C$585,2) -> 92.59 | L28: =LARGE(Datos_CMg!$C$578:$C$585,3) -> 88.38 | M28: =LARGE(Datos_CMg!$C$578:$C$585,4) -> 87.4
A29: 2022-01-26 | B29: =Datos_CMg!$D$602 -> 2022 | C29: =(SMALL(Datos_CMg!$C$611:$C$619,1)+SMALL(Datos_CMg!$C$611:$C$619,2)+SMALL(Datos_CMg!$C$611:$C$619,3)+SMALL(Datos_CMg!$C$611:$C$619,4))/4 -> 0 | D29: =(LARGE($F29:$M29,1)+LARGE($F29:$M29,2)+LARGE($F29:$M29,3)+LARGE($F29:$M29,4))/4 -> 207.525 | E29: =D29-C29 -> 207.525 | F29: =LARGE(Datos_CMg!$C$621:$C$625,1) -> 175.29 | G29: =LARGE(Datos_CMg!$C$621:$C$625,2) -> 171.08 | H29: =LARGE(Datos_CMg!$C$621:$C$625,3) -> 159.33 | I29: =LARGE(Datos_CMg!$C$621:$C$625,4) -> 152.3 | J29: =LARGE(Datos_CMg!$C$602:$C$609,1) -> 210.18 | K29: =LARGE(Datos_CMg!$C$602:$C$609,2) -> 210.18 | L29: =LARGE(Datos_CMg!$C$602:$C$609,3) -> 210.18 | M29: =LARGE(Datos_CMg!$C$602:$C$609,4) -> 199.56
A30: 2022-01-27 | B30: =Datos_CMg!$D$626 -> 2022 | C30: =(SMALL(Datos_CMg!$C$635:$C$643,1)+SMALL(Datos_CMg!$C$635:$C$643,2)+SMALL(Datos_CMg!$C$635:$C$643,3)+SMALL(Datos_CMg!$C$635:$C$643,4))/4 -> 63.3975 | D30: =(LARGE($F30:$M30,1)+LARGE($F30:$M30,2)+LARGE($F30:$M30,3)+LARGE($F30:$M30,4))/4 -> 214.275 | E30: =D30-C30 -> 150.8775 | F30: =LARGE(Datos_CMg!$C$645:$C$649,1) -> 114.55 | G30: =LARGE(Datos_CMg!$C$645:$C$649,2) -> 114.55 | H30: =LARGE(Datos_CMg!$C$645:$C$649,3) -> 114.55 | I30: =LARGE(Datos_CMg!$C$645:$C$649,4) -> 114.55 | J30: =LARGE(Datos_CMg!$C$626:$C$633,1) -> 229.47 | K30: =LARGE(Datos_CMg!$C$626:$C$633,2) -> 220.09 | L30: =LARGE(Datos_CMg!$C$626:$C$633,3) -> 211.09 | M30: =LARGE(Datos_CMg!$C$626:$C$633,4) -> 196.45
A31: 2022-01-28 | B31: =Datos_CMg!$D$650 -> 2022 | C31: =(SMALL(Datos_CMg!$C$659:$C$667,1)+SMALL(Datos_CMg!$C$659:$C$667,2)+SMALL(Datos_CMg!$C$659:$C$667,3)+SMALL(Datos_CMg!$C$659:$C$667,4))/4 -> 42.2425 | D31: =(LARGE($F31:$M31,1)+LARGE($F31:$M31,2)+LARGE($F31:$M31,3)+LARGE($F31:$M31,4))/4 -> 124.29 | E31: =D31-C31 -> 82.0475 | F31: =LARGE(Datos_CMg!$C$669:$C$673,1) -> 97.22 | G31: =LARGE(Datos_CMg!$C$669:$C$673,2) -> 85.65 | H31: =LARGE(Datos_CMg!$C$669:$C$673,3) -> 85.65 | I31: =LARGE(Datos_CMg!$C$669:$C$673,4) -> 85.65 | J31: =LARGE(Datos_CMg!$C$650:$C$657,1) -> 146.45 | K31: =LARGE(Datos_CMg!$C$650:$C$657,2) -> 138.11 | L31: =LARGE(Datos_CMg!$C$650:$C$657,3) -> 106.3 | M31: =LARGE(Datos_CMg!$C$650:$C$657,4) -> 106.3
A32: 2022-01-29 | B32: =Datos_CMg!$D$674 -> 2022 | C32: =(SMALL(Datos_CMg!$C$683:$C$691,1)+SMALL(Datos_CMg!$C$683:$C$691,2)+SMALL(Datos_CMg!$C$683:$C$691,3)+SMALL(Datos_CMg!$C$683:$C$691,4))/4 -> 0 | D32: =(LARGE($F32:$M32,1)+LARGE($F32:$M32,2)+LARGE($F32:$M32,3)+LARGE($F32:$M32,4))/4 -> 108.37 | E32: =D32-C32 -> 108.37 | F32: =LARGE(Datos_CMg!$C$693:$C$697,1) -> 115.98 | G32: =LARGE(Datos_CMg!$C$693:$C$697,2) -> 115.38 | H32: =LARGE(Datos_CMg!$C$693:$C$697,3) -> 112.62 | I32: =LARGE(Datos_CMg!$C$693:$C$697,4) -> 85.7 | J32: =LARGE(Datos_CMg!$C$674:$C$681,1) -> 89.5 | K32: =LARGE(Datos_CMg!$C$674:$C$681,2) -> 81.85 | L32: =LARGE(Datos_CMg!$C$674:$C$681,3) -> 81.85 | M32: =LARGE(Datos_CMg!$C$674:$C$681,4) -> 81.85
A33: 2022-01-30 | B33: =Datos_CMg!$D$698 -> 2022 | C33: =(SMALL(Datos_CMg!$C$707:$C$715,1)+SMALL(Datos_CMg!$C$707:$C$715,2)+SMALL(Datos_CMg!$C$707:$C$715,3)+SMALL(Datos_CMg!$C$707:$C$715,4))/4 -> 0 | D33: =(LARGE($F33:$M33,1)+LARGE($F33:$M33,2)+LARGE($F33:$M33,3)+LARGE($F33:$M33,4))/4 -> 79.4675 | E33: =D33-C33 -> 79.4675 | F33: =LARGE(Datos_CMg!$C$717:$C$721,1) -> 82.26 | G33: =LARGE(Datos_CMg!$C$717:$C$721,2) -> 80.53 | H33: =LARGE(Datos_CMg!$C$717:$C$721,3) -> 78.82 | I33: =LARGE(Datos_CMg!$C$717:$C$721,4) -> 75.74 | J33: =LARGE(Datos_CMg!$C$698:$C$705,1) -> 76.26 | K33: =LARGE(Datos_CMg!$C$698:$C$705,2) -> 75.03 | L33: =LARGE(Datos_CMg!$C$698:$C$705,3) -> 74.99 | M33: =LARGE(Datos_CMg!$C$698:$C$705,4) -> 74.78
A34: 2022-01-31 | B34: =Datos_CMg!$D$722 -> 2022 | C34: =(SMALL(Datos_CMg!$C$731:$C$739,1)+SMALL(Datos_CMg!$C$731:$C$739,2)+SMALL(Datos_CMg!$C$731:$C$739,3)+SMALL(Datos_CMg!$C$731:$C$739,4))/4 -> 38.73 | D34: =(LARGE($F34:$M34,1)+LARGE($F34:$M34,2)+LARGE($F34:$M34,3)+LARGE($F34:$M34,4))/4 -> 84.78 | E34: =D34-C34 -> 46.05 | F34: =LARGE(Datos_CMg!$C$741:$C$745,1) -> 85.12 | G34: =LARGE(Datos_CMg!$C$741:$C$745,2) -> 85.1 | H34: =LARGE(Datos_CMg!$C$741:$C$745,3) -> 84.48 | I34: =LARGE(Datos_CMg!$C$741:$C$745,4) -> 84.42 | J34: =LARGE(Datos_CMg!$C$722:$C$729,1) -> 82.63 | K34: =LARGE(Datos_CMg!$C$722:$C$729,2) -> 79.39 | L34: =LARGE(Datos_CMg!$C$722:$C$729,3) -> 72.61 | M34: =LARGE(Datos_CMg!$C$722:$C$729,4) -> 70.73
A35: 2022-02-01 | B35: =Datos_CMg!$D$746 -> 2022 | C35: =(SMALL(Datos_CMg!$C$755:$C$763,1)+SMALL(Datos_CMg!$C$755:$C$763,2)+SMALL(Datos_CMg!$C$755:$C$763,3)+SMALL(Datos_CMg!$C$755:$C$763,4))/4 -> 54.9825 | D35: =(LARGE($F35:$M35,1)+LARGE($F35:$M35,2)+LARGE($F35:$M35,3)+LARGE($F35:$M35,4))/4 -> 158.3525 | E35: =D35-C35 -> 103.37 | F35: =LARGE(Datos_CMg!$C$765:$C$769,1) -> 185.74 | G35: =LARGE(Datos_CMg!$C$765:$C$769,2) -> 185.74 | H35: =LARGE(Datos_CMg!$C$765:$C$769,3) -> 155.56 | I35: =LARGE(Datos_CMg!$C$765:$C$769,4) -> 106.37 | J35: =LARGE(Datos_CMg!$C$746:$C$753,1) -> 83.77 | K35: =LARGE(Datos_CMg!$C$746:$C$753,2) -> 83.77 | L35: =LARGE(Datos_CMg!$C$746:$C$753,3) -> 83.77 | M35: =LARGE(Datos_CMg!$C$746:$C$753,4) -> 83.39
A36: 2022-02-02 | B36: =Datos_CMg!$D$770 -> 2022 | C36: =(SMALL(Datos_CMg!$C$779:$C$787,1)+SMALL(Datos_CMg!$C$779:$C$787,2)+SMALL(Datos_CMg!$C$779:$C$787,3)+SMALL(Datos_CMg!$C$779:$C$787,4))/4 -> 0.045 | D36: =(LARGE($F36:$M36,1)+LARGE($F36:$M36,2)+LARGE($F36:$M36,3)+LARGE($F36:$M36,4))/4 -> 177.7325 | E36: =D36-C36 -> 177.6875 | F36: =LARGE(Datos_CMg!$C$789:$C$793,1) -> 139.51 | G36: =LARGE(Datos_CMg!$C$789:$C$793,2) -> 119.45 | H36: =LARGE(Datos_CMg!$C$789:$C$793,3) -> 97.36 | I36: =LARGE(Datos_CMg!$C$789:$C$793,4) -> 93.02 | J36: =LARGE(Datos_CMg!$C$770:$C$777,1) -> 183.45 | K36: =LARGE(Datos_CMg!$C$770:$C$777,2) -> 183.45 | L36: =LARGE(Datos_CMg!$C$770:$C$777,3) -> 177.02 | M36: =LARGE(Datos_CMg!$C$770:$C$777,4) -> 167.01
A37: 2022-02-03 | B37: =Datos_CMg!$D$794 -> 2022 | C37: =(SMALL(Datos_CMg!$C$803:$C$811,1)+SMALL(Datos_CMg!$C$803:$C$811,2)+SMALL(Datos_CMg!$C$803:$C$811,3)+SMALL(Datos_CMg!$C$803:$C$811,4))/4 -> 34.06 | D37: =(LARGE($F37:$M37,1)+LARGE($F37:$M37,2)+LARGE($F37:$M37,3)+LARGE($F37:$M37,4))/4 -> 111.845 | E37: =D37-C37 -> 77.785 | F37: =LARGE(Datos_CMg!$C$813:$C$817,1) -> 113.9 | G37: =LARGE(Datos_CMg!$C$813:$C$817,2) -> 109.75 | H37: =LARGE(Datos_CMg!$C$813:$C$817,3) -> 108.91 | I37: =LARGE(Datos_CMg!$C$813:$C$817,4) -> 108.42 | J37: =LARGE(Datos_CMg!$C$794:$C$801,1) -> 114.82 | K37: =LARGE(Datos_CMg!$C$794:$C$801,2) -> 106.25 | L37: =LARGE(Datos_CMg!$C$794:$C$801,3) -> 99.55 | M37: =LARGE(Datos_CMg!$C$794:$C$801,4) -> 85.46
A38: 2022-02-04 | B38: =Datos_CMg!$D$818 -> 2022 | C38: =(SMALL(Datos_CMg!$C$827:$C$835,1)+SMALL(Datos_CMg!$C$827:$C$835,2)+SMALL(Datos_CMg!$C$827:$C$835,3)+SMALL(Datos_CMg!$C$827:$C$835,4))/4 -> 25.0975 | D38: =(LARGE($F38:$M38,1)+LARGE($F38:$M38,2)+LARGE($F38:$M38,3)+LARGE($F38:$M38,4))/4 -> 99.595 | E38: =D38-C38 -> 74.4975 | F38: =LARGE(Datos_CMg!$C$837:$C$841,1) -> 94.99 | G38: =LARGE(Datos_CMg!$C$837:$C$841,2) -> 87.73 | H38: =LARGE(Datos_CMg!$C$837:$C$841,3) -> 87.52 | I38: =LARGE(Datos_CMg!$C$837:$C$841,4) -> 86.58 | J38: =LARGE(Datos_CMg!$C$818:$C$825,1) -> 106.26 | K38: =LARGE(Datos_CMg!$C$818:$C$825,2) -> 102.41 | L38: =LARGE(Datos_CMg!$C$818:$C$825,3) -> 94.72 | M38: =LARGE(Datos_CMg!$C$818:$C$825,4) -> 93.63
A39: 2022-02-05 | B39: =Datos_CMg!$D$842 -> 2022 | C39: =(SMALL(Datos_CMg!$C$851:$C$859,1)+SMALL(Datos_CMg!$C$851:$C$859,2)+SMALL(Datos_CMg!$C$851:$C$859,3)+SMALL(Datos_CMg!$C$851:$C$859,4))/4 -> 0 | D39: =(LARGE($F39:$M39,1)+LARGE($F39:$M39,2)+LARGE($F39:$M39,3)+LARGE($F39:$M39,4))/4 -> 83.2575 | E39: =D39-C39 -> 83.2575 | F39: =LARGE(Datos_CMg!$C$861:$C$865,1) -> 82.75 | G39: =LARGE(Datos_CMg!$C$861:$C$865,2) -> 82.75 | H39: =LARGE(Datos_CMg!$C$861:$C$865,3) -> 80.81 | I39: =LARGE(Datos_CMg!$C$861:$C$865,4) -> 80.55 | J39: =LARGE(Datos_CMg!$C$842:$C$849,1) -> 84.59 | K39: =LARGE(Datos_CMg!$C$842:$C$849,2) -> 82.94 | L39: =LARGE(Datos_CMg!$C$842:$C$849,3) -> 81.82 | M39: =LARGE(Datos_CMg!$C$842:$C$849,4) -> 79.35
A40: 2022-02-06 | B40: =Datos_CMg!$D$866 -> 2022 | C40: =(SMALL(Datos_CMg!$C$875:$C$883,1)+SMALL(Datos_CMg!$C$875:$C$883,2)+SMALL(Datos_CMg!$C$875:$C$883,3)+SMALL(Datos_CMg!$C$875:$C$883,4))/4 -> 15.72 | D40: =(LARGE($F40:$M40,1)+LARGE($F40:$M40,2)+LARGE($F40:$M40,3)+LARGE($F40:$M40,4))/4 -> 85.85 | E40: =D40-C40 -> 70.13 | F40: =LARGE(Datos_CMg!$C$885:$C$889,1) -> 86.96 | G40: =LARGE(Datos_CMg!$C$885:$C$889,2) -> 86.54 | H40: =LARGE(Datos_CMg!$C$885:$C$889,3) -> 85.55 | I40: =LARGE(Datos_CMg!$C$885:$C$889,4) -> 84.35 | J40: =LARGE(Datos_CMg!$C$866:$C$873,1) -> 80.9 | K40: =LARGE(Datos_CMg!$C$866:$C$873,2) -> 77.07 | L40: =LARGE(Datos_CMg!$C$866:$C$873,3) -> 75.06 | M40: =LARGE(Datos_CMg!$C$866:$C$873,4) -> 72.59
...

Sheet Sensibilidad_PPA
A1: Sensibilidad al precio del PPA de compra (caso base 2023–2026, 4 h)
A2: El costo de carga a spot del caso base (≈15 USD/MWh) es inferior al PPA en todo el rango evaluado; el contrato destruye valor bajo cualquier precio.
A4: Precio PPA (USD/MWh) | B4: Costo carga a PPA (USD/año) | C4: Costo carga a spot (USD/año) | D4: Sobrecosto del PPA (USD/año) | E4: ¿Conviene el PPA?
A5: 22 | B5: =Supuestos!$B$16*A5 -> 144540 | C5: =Supuestos!$B$16*Resultado_Anual!$B$10 -> 101110.32 | D5: =B5-C5 -> 43429.682 | E5: =IF(D5>0,"No — destruye valor","Sí") -> No — destruye valor
A6: 25 | B6: =Supuestos!$B$16*A6 -> 164250 | C6: =Supuestos!$B$16*Resultado_Anual!$B$10 -> 101110.32 | D6: =B6-C6 -> 63139.682 | E6: =IF(D6>0,"No — destruye valor","Sí") -> No — destruye valor
A7: 28 | B7: =Supuestos!$B$16*A7 -> 183960 | C7: =Supuestos!$B$16*Resultado_Anual!$B$10 -> 101110.32 | D7: =B7-C7 -> 82849.682 | E7: =IF(D7>0,"No — destruye valor","Sí") -> No — destruye valor
A8: 31 | B8: =Supuestos!$B$16*A8 -> 203670 | C8: =Supuestos!$B$16*Resultado_Anual!$B$10 -> 101110.32 | D8: =B8-C8 -> 102559.68 | E8: =IF(D8>0,"No — destruye valor","Sí") -> No — destruye valor
A9: 34 | B9: =Supuestos!$B$16*A9 -> 223380 | C9: =Supuestos!$B$16*Resultado_Anual!$B$10 -> 101110.32 | D9: =B9-C9 -> 122269.68 | E9: =IF(D9>0,"No — destruye valor","Sí") -> No — destruye valor
A11: Costo de carga a spot = energía de carga (6.570 MWh) × precio medio de carga en banda solar (caso base 2023–2026, ≈15 USD/MWh). Sobrecosto = costo a PPA − costo a spot.
